<?xml version='1.0'?>
  <sdf version='1.4'>
    <model name="micromouse">
    <static>false</static>
    <link name='chassis'>
      <pose>0 0 .01 0 0 0</pose>
      <collision name='collision'>
        <geometry>
          <box>
            <size>.1 .075 .02</size>
          </box>
        </geometry>
      </collision>
      <visual name='visual'>
        <geometry>
          <box>
            <size>.1 .075 .02</size>
          </box>
        </geometry>
      </visual>
    </link>

    <link name="left_wheel_front">
      <pose>0.1 0.13 0.1 0 1.5707 1.5707</pose>
      <collision name="collision">
        <geometry>
          <cylinder>
            <radius>.013</radius>
            <length>.0085</length>
          </cylinder>
        </geometry>
      </collision>
      <visual name="visual">
        <geometry>
          <cylinder>
            <radius>.013</radius>
            <length>.0085</length>
          </cylinder>
        </geometry>
      </visual>
    </link>

    <link name="right_wheel_front">
      <pose>0.1 -0.13 0.1 0 1.5707 1.5707</pose>
      <collision name="collision">
        <geometry>
          <cylinder>
            <radius>.013</radius>
            <length>.0085</length>
          </cylinder>
        </geometry>
      </collision>
      <visual name="visual">
        <geometry>
          <cylinder>
            <radius>.013</radius>
            <length>.0085</length>
          </cylinder>
        </geometry>
      </visual>
    </link>

    <joint type="revolute" name="left_wheel_hinge_front">
      <pose>0 0 -0.03 0 0 0</pose>
      <child>left_wheel_front</child>
      <parent>chassis</parent>
      <axis>
        <xyz>0 1 0</xyz>
      </axis>
    </joint>

    <joint type="revolute" name="right_wheel_hinge_front">
      <pose>0 0 0.03 0 0 0</pose>
      <child>right_wheel_front</child>
      <parent>chassis</parent>
      <axis>
        <xyz>0 1 0</xyz>
      </axis>
    </joint>
  </model>
</sdf>